Workbook

Sheet DATA US
A1: DAFTAR CALON PESERTA UJIAN SEKOLAH TAHUN PELAJARAN 2024/2025
A2: (US 1)
A4: Nama Sekolah | D4: : SMK BINA INDUSTRI
A5: Alamat | D5: : JL.Alun-alun Kp.Cibarengkok Ds.Jatiwangi
A6: No. Telpon | D6: : 021- 82622655
A7: Kelurahan | D7: : Jatiwangi
A8: Kecamatan | D8: : Cikarang Barat
A9: Kode Pos | D9: : .17849
A10: Status Akreditasi | D10: :
A12: Nomor | D12: Nama Calon Peserta | E12: L/P | F12: Tempat Lahir | G12: Tanggal/Tahun Lahir | H12: Agama | I12: Nama Orang Tua | J12: Alamat Orang Tua / Wali | K12: STTB Setingkat lebih rendah | M12: Tahun Raport pada kelas
A13: Urut | B13: NIS | C13: NISN | K13: Nomor | L13: Tahun | M13: X | N13: XI | O13: XII
A14: TEKNIK dan BISNIS SEPEDA MOTOR
A15: 1 | B15: 222310001 | C15: 0072124779 | D15: ADAM ZAKIE RAMADHAN | E15: L | F15: BEKASI | G15: 23 April 2007 | H15: Islam | I15: BOIH | J15: Kp. Lubang Buaya RT 02/08 Ds. Lubang Buaya Kec. Setu | K15: MTs-22 100 155202 | L15: 2022 | M15: 2022/2023 | N15: 2023/2024 | O15: 2024/2025
A16: 2 | B16: 222310002 | C16: 0077315289 | D16: AKSAY SETIA AJI | E16: L | F16: BEKASI | G16: 24 Maret 2007 | H16: Islam | I16: TUGIYANTO | J16: Kp. Rawa Julang RT 004/002 Ds. Mekarwangi Kec. Cik-Bar | K16: Mts-22 100155470 | L16: 2022 | M16: 2022/2023 | N16: 2023/2024 | O16: 2024/2025
A17: 3 | B17: 222310003 | C17: 0078124071 | D17: ALFRIYANSYAH FINDO SALMAN | E17: L | F17: BEKASI | G17: 30 Juni 2007 | H17: Islam | I17: SUROSO | J17: Jl. Laik Jalan Blok C No. 2 Perhubdat RT 002/012 Ds. Cibuntu Kec. Cibitung | K17: MTs-22 100155472 | L17: 2022 | M17: 2022/2023 | N17: 2023/2024 | O17: 2024/2025
A18: 4 | B18: 222310004 | C18: 0134157802 | D18: ARIEF OKTA PRATAMA | E18: L | F18: CIAMIS | G18: 20 Oktober 2006 | H18: Islam | I18: ARLEX FEBRI SURIANTO | J18: Kp. Jarakosta RT 002/001 Ds. Danau Indah Kec. Cik-Bar | K18: DN-02/D-SMP/K13/0087535 | L18: 2022 | M18: 2022/2023 | N18: 2023/2024 | O18: 2024/2025
A19: 5 | B19: 222310005 | C19: 0072858452 | D19: DEDEN RIZKY SAPUTRA | E19: L | F19: BEKASI | G19: 8 Agustus 2007 | H19: Islam | I19: SANDIH | J19: Kp. Babakan RT 002/001 Ds. Jatiwangi Kec. Cik-Bar | K19: MTs-22 100155210 | L19: 2022 | M19: 2022/2023 | N19: 2023/2024 | O19: 2024/2025
A20: 6 | B20: 222310006 | C20: 0073210618 | D20: DENI RAHMAT SAPUTRA | E20: L | F20: BEKASI | G20: 8 Agustus 2007 | H20: Islam | I20: SANDIH | J20: Kp. Babakan RT 002/001 Ds. Jatiwangi Kec. Cik-Bar | K20: MTs-22 100155213 | L20: 2022 | M20: 2022/2023 | N20: 2023/2024 | O20: 2024/2025
A21: 7 | B21: 222310007 | C21: 0072762394 | D21: DITO AJI TRI CAHYO | E21: L | F21: BEKASI | G21: 14 April 2007 | H21: Islam | I21: BUANG SANTOSO (ALM) | J21: Kp. Rawa Julang RT 003/002 Ds. Mekarwangi | K21: MTs-22 100155214 | L21: 2022 | M21: 2022/2023 | N21: 2023/2024 | O21: 2024/2025
A22: 8 | B22: 222310008 | C22: 0078607611 | D22: EGA MAULANA RAYHAN | E22: L | F22: BEKASI | G22: 10 Januari 2007 | H22: Islam | I22: NAMIN SUWANDA | J22: Kp. Cibarengkok RT 001/002 Ds. Jatiwangi Kec. Cik-Bar | K22: MTs-22100155215 | L22: 2022 | M22: 2022/2023 | N22: 2023/2024 | O22: 2024/2025
A23: 9 | B23: 222310009 | C23: 0071107397 | D23: FAUZA WIJAYA | E23: L | F23: BEKASI | G23: 3 Juli 2007 | H23: Islam | I23: MURKIM | J23: Kp. Rawa Julang RT 001/001 Ds. Mekarwangi Kec. Cik-Bar | K23: MTs-22100156173 | L23: 2022 | M23: 2022/2023 | N23: 2023/2024 | O23: 2024/2025
A24: 10 | B24: 222310010 | C24: 0072628439 | D24: FAZRI RAMDANI AL BASIT | E24: L | F24: BEKASI | G24: 3 Oktober 2007 | H24: Islam | I24: MUHAMAD SYARIF | J24: Kp. Jarakosta RT 001/001 Ds. Danau Indah | K24: DN-02/D-SMP/K13/0087469 | L24: 2022 | M24: 2022/2023 | N24: 2023/2024 | O24: 2024/2025
A25: 11 | B25: 222310011 | C25: 0064029233 | D25: INTO | E25: L | F25: BEKASI | G25: 24 Februari 2006 | H25: Islam | I25: KARNO BIN EMUK | J25: Kp. Babakan RT 002/001 Ds. Jatiwangi Kec. Cik-Bar | K25: DN-02/D-SMPK13/0087607 | L25: 2022 | M25: 2022/2023 | N25: 2023/2024 | O25: 2024/2025
A26: 12 | B26: 222310012 | C26: 0075073374 | D26: IRPAN MAULANA | E26: L | F26: BEKASI | G26: 19 Januari 2007 | H26: Islam | I26: SALIM | J26: Kp. Jarakosta Kebon Kelapa RT 006/004 Ds. Sukadanau Kec. Cik-Bar | K26: DN-02/D-SMP/K13/0087579 | L26: 2022 | M26: 2022/2023 | N26: 2023/2024 | O26: 2024/2025
... A38: 24 | B38: 222310023 | C38: 0078400677 | D38: NAUFAL ASAD | E38: L | F38: BEKASI | G38: 5 Agustus 2007 | H38: Islam | I38: ABDUL HASSIM | J38: Kp. Rawa Julang RT 004/002 Ds. Mekarwangi Kec. Cik-Bar | K38: MTs-11 100155228 | L38: 2022 | M38: 2022/2023 | N38: 2023/2024 | O38: 2024/2025
A39: 25 | B39: 222310147 | C39: 0061172472 | D39: PAHRUDIN HIDAYAT | F39: BEKASI | G39: 23 Agustus 2006 | H39: Islam | I39: NEMAT | J39: Desa Ganda Mekar Kec. CIkarang Barat Kab. Bekasi, Jawa Barat | K39: MTs-22 100155486 | L39: 2022 | M39: 2022/2023 | N39: 2023/2024 | O39: 2024/2025
A40: 26 | B40: 222310024 | C40: 0071750896 | D40: RAFA ARDIANSYAH | E40: L | F40: BEKASI | G40: 5 Maret 2007 | H40: Islam | I40: PURWADU | J40: Kp. Rawa Julang RT 004/002 Ds. Mekarwangi Kec. Cik-Bar | K40: MTs-22 100155524 | L40: 2022 | M40: 2022/2023 | N40: 2023/2024 | O40: 2024/2025
A41: 27 | B41: 222310025 | C41: 0064628744 | D41: ROY TANSRI ARTAMA | E41: L | F41: SRAGEN | G41: 02 Mei 2007 | H41: Islam | I41: SRI YONO | J41: Kp. Mariuk Rt 003/005 Desa Gandamekar, Kec. Cikarang Barat | K41: DN-02/D-SMP/K13/0087487 | L41: 2022 | M41: 2022/2023 | N41: 2023/2024 | O41: 2024/2025
A42: 28 | B42: 222310026 | C42: 0071829562 | D42: SATRYO PASHA RAMANDA | E42: L | F42: TANGGERANG | G42: 23 Januari 2007 | H42: Islam | I42: DWINANTO WIBOWO | J42: Perum Grand Mutiara Gading Blok I6 No. 16 Telajung, Cik-Bar | K42: MTs-22 100156219 | L42: 2022 | M42: 2022/2023 | N42: 2023/2024 | O42: 2024/2025
A43: 29 | B43: 222310027 | C43: 0078911090 | D43: SOBRIYANTO | E43: L | F43: BEKASI | G43: 16 Januari 2007 | H43: Islam | I43: IDUT | J43: Kp. Cisaat RT 013/006 Ds. Kertarahayu Kec. Setu Kab. Bekasi | K43: DN-02/D-SMP/K13/0108394 | L43: 2022 | M43: 2022/2023 | N43: 2023/2024 | O43: 2024/2025
A44: 30 | B44: 222310028 | C44: 0078505225 | D44: WANA SUMARNA | E44: L | F44: BEKASI | G44: 4 September 2007 | H44: Islam | I44: UMAR SUMARNA | J44: Kp. Babakan RT 002/010 Ds. Telajung Kec. Cik-Bar Kab. Bekasi | K44: MTs- 22 100155622 | L44: 2022 | M44: 2022/2023 | N44: 2023/2024 | O44: 2024/2025
A45: 31 | B45: 222310029 | C45: 0071843924 | D45: WISNU BINTANG BERLIAN | E45: L | F45: BEKASI | G45: 16 April 2007 | H45: Islam | I45: TOMPUL | J45: Kp. Rawa Julang Ds. Mekarwangi Kec. Cik-Bar Kab. Bekasi | K45: MTs-22 100155498 | L45: 2022 | M45: 2022/2023 | N45: 2023/2024 | O45: 2024/2025
A46: 32 | B46: 242512086 | C46: 0075620652 | D46: HAZAQ OSEAN RAFIF | E46: L | F46: MAJALENGKA | G46: 07 Februari 2007 | H46: Islam | I46: Hendrik | J46: Desa telajung RT 001 RW 010 No.225 Kec.Cikarang Barat, kab Bekasi | K46: MTs-22 1001154223 | L46: 2022 | M46: 2022/2023 | N46: 2023/2024 | O46: 2024/2025
A47: 33 | B47: 222310030 | C47: 0076215153 | D47: AA DITIA FRATAMA | E47: L | F47: BEKASI | G47: 28 Juni 2007 | H47: Islam | I47: DEDI | J47: Kp. Cikedokan RT 002/006 Ds. Cikedokan | K47: MTs-22 100155534 | L47: 2022 | M47: 2022/2023 | N47: 2023/2024 | O47: 2024/2025
A48: 34 | B48: 222310031 | C48: 0064677701 | D48: ABDULLAH AHMAD FAUZAN | E48: L | F48: BREBES | G48: 26 Oktober 2006 | H48: Islam | I48: AHMAD SUJURLIAN | J48: Kp. Jarakosta RT 001/001 Ds. Danau Indah | K48: MTs-22 100140455 | L48: 2022 | M48: 2022/2023 | N48: 2023/2024 | O48: 2024/2025
A49: 35 | B49: 222310032 | C49: 0076929544 | D49: ANDIKA SAPUTRA | E49: L | F49: BEKASI | G49: 21 Mei 2007 | H49: Islam | I49: NARTA | J49: Kp. Rawa Julang RT 004/002 Ds. Mekarwangi Kec. Cikarang Barat Kab. Bekasi | K49: MTs-22 100155205 | L49: 2022 | M49: 2022/2023 | N49: 2023/2024 | O49: 2024/2025
A50: 36 | B50: 222310033 | C50: 0061065498 | D50: ARFHANSYAH PUTRA | E50: L | F50: BEKASI | G50: 18 Juli 2006 | H50: Islam | I50: AMIN AHMADI | J50: Kp. Kamurang RT 001/003 Ds. Cikedokan Kec. Cikarang Barat Kab. Bekasi | K50: MTs-22 100155274 | L50: 2022 | M50: 2022/2023 | N50: 2023/2024 | O50: 2024/2025
A51: 37 | B51: 222310034 | C51: 0077550363 | D51: CAESAR DANDI TRI PERKASA | E51: L | F51: BEKASI | G51: 39176 | H51: Islam | I51: LAMANSYAH ERWIN | J51: Kp. Cibarengkok RT 04/02 No.88 Ds. Jatiwangi | K51: DN-02/D-SMP/K13/ 0087432 | L51: 2022 | M51: 2022/2023 | N51: 2023/2024 | O51: 2024/2025
A52: 38 | B52: 222310035 | C52: 0074682824 | D52: DIMAS RIMUNANDAR | E52: L | F52: BEKASI | G52: 13 April 2007 | H52: Islam | I52: KAJI NURFAIDZI | J52: Kp. Cisaat RT 014/006 Ds. Kertarahayu | K52: DN-02/D-SMP/K13/ 0108336 | L52: 2022 | M52: 2022/2023 | N52: 2023/2024 | O52: 2024/2025
A53: 39 | B53: 222310036 | C53: 0075646043 | D53: DINAR RADITIYA PRATAMA | E53: L | F53: BEKASI | G53: 20 Maret 2007 | H53: Islam | I53: EKA RADIANSYAH | J53: Kp. Cibuntu RT 001/007 Ds. Cibuntu Kec. Cibitung Kab. Bekasi | K53: MTs-22 100155156 | L53: 2022 | M53: 2022/2023 | N53: 2023/2024 | O53: 2024/2025
...

Sheet TSM
A1: NAMA SISWA | B1: NIS | C1: TEMPAT | D1: TANGGAL LAHIR | E1: Program Keahlian | F1: JK | G1: PAI | H1: PPKN | I1: Bhs. Indonesia | J1: Matematika | K1: Sejarah Indonesia | L1: Bhs. Inggris | M1: Seni Budaya | N1: PJOK | O1: Bahasa Sunda | P1: SIMULASI DIGITAL | Q1: FISIKA | R1: KIMIA | S1: Dasar Program | T1: Kompetensi Keahlian | U1: rata rata | V1: PKK | W1: NAMA ORTU | X1: NISN | Y1: NO. IJAZAH
A2: ='DATA US'!D47 -> AA DITIA FRATAMA | B2: ='DATA US'!B47 -> 222310030 | C2: Bekasi | D2: 28 Juni 2007 | E2: Teknik Dan Bisnis Sepeda Motor | F2: L | G2: 84.88 | H2: 85.64 | I2: 89.66 | J2: 83.86 | K2: 84 | L2: 83.76 | M2: 81 | N2: 85.1 | O2: 83 | P2: 77 | Q2: 83.5 | R2: 82.5 | S2: 82 | T2: 85.841667 | U2: 83.841667 | V2: 83.566667 | W2: ='DATA US'!I47 -> DEDI | X2: ='DATA US'!C47 -> 0076215153 | Y2: 141202510111852
A3: ='DATA US'!D48 -> ABDULLAH AHMAD FAUZAN | B3: ='DATA US'!B48 -> 222310031 | C3: Brebes | D3: 26 Oktober 2006 | E3: Teknik Dan Bisnis Sepeda Motor | F3: L | G3: 82.92 | H3: 81.58 | I3: 87.2 | J3: 80.62 | K3: 80.5 | L3: 80.9 | M3: 80.5 | N3: 85.3 | O3: 80.5 | P3: 80.5 | Q3: 83 | R3: 82 | S3: 79.166667 | T3: 79 | U3: 81.969333 | V3: 82.566667 | W3: ='DATA US'!I48 -> AHMAD SUJURLIAN | X3: ='DATA US'!C48 -> 0064677701 | Y3: 141202510111865
A4: ='DATA US'!D15 -> ADAM ZAKIE RAMADHAN | B4: ='DATA US'!B15 -> 222310001 | C4: Bekasi | D4: 23 April 2007 | E4: Teknik Dan Bisnis Sepeda Motor | F4: L | G4: 84.44 | H4: 85.7 | I4: 90.58 | J4: 89.92 | K4: 85 | L4: 85.24 | M4: 81.5 | N4: 84.9 | O4: 84.5 | P4: 80.5 | Q4: 86 | R4: 83.5 | S4: 80.333333 | T4: 84.5 | U4: 84.307333 | V4: 85.366667 | W4: ='DATA US'!I15 -> BOIH | X4: ='DATA US'!C15 -> 0072124779 | Y4: 141202510111886
A5: ='DATA US'!D72 -> ADHITYA PRATAMA | B5: ='DATA US'!B72 -> 222310056 | C5: Bekasi | D5: 27 Juni 2006 | E5: Teknik Dan Bisnis Sepeda Motor | F5: L | G5: 83.08 | H5: 85.2 | I5: 88.06 | J5: 83.8 | K5: 86 | L5: 84.48 | M5: 82 | N5: 85.8 | O5: 84.5 | P5: 81.5 | Q5: 84 | R5: 86.5 | S5: 82.333333 | T5: 85.058333 | U5: 84.336 | V5: 84.336 | W5: ='DATA US'!I72 -> TUGIYO | X5: ='DATA US'!C72 -> 0069773854 | Y5: 141202510111898
A6: ='DATA US'!D73 -> AHMAD ROZIKIN | B6: ='DATA US'!B73 -> 222310057 | C6: Brebes | D6: 13 Agustus 2006 | E6: Teknik Dan Bisnis Sepeda Motor | F6: L | G6: 82.33 | H6: 83.8 | I6: 89.89 | J6: 87.38 | K6: 82 | L6: 83.02 | M6: 82 | N6: 81.4 | O6: 82.5 | P6: 77.5 | Q6: 83 | R6: 83.5 | S6: 79.833333 | T6: 85.875 | U6: 83.287667 | V6: 83.287667 | W6: ='DATA US'!I73 -> DIWANTO | X6: ='DATA US'!C73 -> 0066401952 | Y6: 141202510111916
A7: ='DATA US'!D74 -> AKBAR | B7: ='DATA US'!B74 -> 222310058 | C7: Purbalingga | D7: 16 Maret 2007 | E7: Teknik Dan Bisnis Sepeda Motor | F7: L | G7: 82.88 | H7: 83.74 | I7: 85.07 | J7: 79.28 | K7: 84 | L7: 83.02 | M7: 83 | N7: 86.8 | O7: 82.5 | P7: 79.5 | Q7: 83 | R7: 84.5 | S7: 79.833333 | T7: 83.883333 | U7: 82.7945 | V7: 82.7945 | W7: ='DATA US'!I74 -> SUKIMAN | X7: ='DATA US'!C74 -> 0072498885 | Y7: 141202510111924
A8: ='DATA US'!D16 -> AKSAY SETIA AJI | B8: ='DATA US'!B16 -> 222310002 | C8: Bekasi | D8: 24 Maret 2007 | E8: Teknik Dan Bisnis Sepeda Motor | F8: L | G8: 83.34 | H8: 83.28 | I8: 86.12 | J8: 88.76 | K8: 85 | L8: 83.22 | M8: 81.5 | N8: 86 | O8: 82.5 | P8: 79 | Q8: 86 | R8: 85 | S8: 79.5 | T8: 85.183333 | U8: 83.684333 | V8: 84.733333 | W8: ='DATA US'!I16 -> TUGIYANTO | X8: ='DATA US'!C16 -> 0077315289 | Y8: 141202510111937
A9: ='DATA US'!D17 -> ALFRIYANSYAH FINDO SALMAN | B9: ='DATA US'!B17 -> 222310003 | C9: Bekasi | D9: 30 Juni 2007 | E9: Teknik Dan Bisnis Sepeda Motor | F9: L | G9: 82.82 | H9: 84.08 | I9: 83.91 | J9: 83.62 | K9: 83 | L9: 82.2 | M9: 81 | N9: 85.7 | O9: 80.5 | P9: 79 | Q9: 84.5 | R9: 82.5 | S9: 75.666667 | T9: 82.875 | U9: 81.724833 | V9: 83.166667 | W9: ='DATA US'!I17 -> SUROSO | X9: ='DATA US'!C17 -> 0078124071 | Y9: 141202510111942
A10: ='DATA US'!D75 -> AMMAR ABDULLAH | B10: ='DATA US'!B75 -> 222310148 | C10: Bekasi | D10: 02 Juni 2007 | E10: Teknik Dan Bisnis Sepeda Motor | F10: L | G10: 84.72 | H10: 84.28 | I10: 88.87 | J10: 87.08 | K10: 86 | L10: 80.74 | M10: 78 | N10: 86.6 | O10: 79.5 | P10: 84.5 | Q10: 78 | R10: 79.5 | S10: 78.5 | T10: 85.408333 | U10: 82.9745 | V10: 82.9745 | W10: ='DATA US'!I75 -> DASIM | X10: ='DATA US'!C75 -> 0076027666 | Y10: 141202510111974
A11: ='DATA US'!D76 -> ANANDA S DEWA | B11: ='DATA US'!B76 -> 222310059 | C11: Bekasi | D11: 28 Februari 2007 | E11: Teknik Dan Bisnis Sepeda Motor | F11: L | G11: 82.77 | H11: 84.62 | I11: 87.53 | J11: 85.5 | K11: 79 | L11: 83.06 | M11: 82 | N11: 84.8 | O11: 81 | P11: 78 | Q11: 83 | R11: 84 | S11: 81 | T11: 84.808333 | U11: 83.110667 | V11: 83.110667 | W11: ='DATA US'!I76 -> NATA SUNANDAR | X11: ='DATA US'!C76 -> 0073486388 | Y11: 141202510111997
A12: ='DATA US'!D49 -> ANDIKA SAPUTRA | B12: ='DATA US'!B49 -> 222310032 | C12: Bekasi | D12: 21 Mei 2007 | E12: Teknik Dan Bisnis Sepeda Motor | F12: L | G12: 84.9 | H12: 84.36 | I12: 89.96 | J12: 89.58 | K12: 86 | L12: 89.42 | M12: 82 | N12: 86.4 | O12: 84.5 | P12: 82.5 | Q12: 83.5 | R12: 84 | S12: 81.833333 | T12: 86.266667 | U12: 85.147667 | V12: 85.266667 | W12: ='DATA US'!I49 -> NARTA | X12: ='DATA US'!C49 -> 0076929544 | Y12: 141202510112001
A13: ='DATA US'!D77 -> ARDIAN PUTRA PRATAMA | B13: ='DATA US'!B77 -> 222310060 | C13: Sragen | D13: 03 April 2007 | E13: Teknik Dan Bisnis Sepeda Motor | F13: L | G13: 81.92 | H13: 83.8 | I13: 89.53 | J13: 83.48 | K13: 85 | L13: 83.56 | M13: 82 | N13: 82.6 | O13: 81.5 | P13: 78.5 | Q13: 84 | R13: 83 | S13: 80.666667 | T13: 86.258333 | U13: 83.487833 | V13: 83.487833 | W13: ='DATA US'!I77 -> MADIYONO | X13: ='DATA US'!C77 -> 0079924122 | Y13: 141202510112029
A14: ='DATA US'!D50 -> ARFHANSYAH PUTRA | B14: ='DATA US'!B50 -> 222310033 | C14: Bekasi | D14: 18 Juli 2006 | E14: Teknik Dan Bisnis Sepeda Motor | F14: L | G14: 82.94 | H14: 82.96 | I14: 87.74 | J14: 82.06 | K14: 84 | L14: 80.56 | M14: 81 | N14: 84.5 | O14: 84.5 | P14: 78 | Q14: 83 | R14: 82.5 | S14: 81 | T14: 83.95 | U14: 82.818 | V14: 83.8 | W14: ='DATA US'!I50 -> AMIN AHMADI | X14: ='DATA US'!C50 -> 0061065498 | Y14: 141202510112033
A15: ='DATA US'!D78 -> ARI SETIAWAN | B15: ='DATA US'!B78 -> 222310062 | C15: Bekasi | D15: 22 Januari 2007 | E15: Teknik Dan Bisnis Sepeda Motor | F15: L | G15: 84.84 | H15: 87.2 | I15: 90.93 | J15: 85.82 | K15: 86 | L15: 88.1 | M15: 82 | N15: 88.8 | O15: 86.5 | P15: 82 | Q15: 85 | R15: 85.5 | S15: 83.333333 | T15: 86.475 | U15: 85.637833 | V15: 85.637833 | W15: ='DATA US'!I78 -> ENDANG S TORINA | X15: ='DATA US'!C78 -> 0075084595 | Y15: 141202510112041
A16: ='DATA US'!D18 -> ARIEF OKTA PRATAMA | B16: ='DATA US'!B18 -> 222310004 | C16: Ciamis | D16: 20 Oktober 2006 | E16: Teknik Dan Bisnis Sepeda Motor | F16: L | G16: 81.98 | H16: 84.6 | I16: 83.56 | J16: 82.8 | K16: 80 | L16: 81.42 | M16: 82 | N16: 84.8 | O16: 81 | P16: 79.5 | Q16: 83 | R16: 83.5 | S16: 77.333333 | T16: 81.333333 | U16: 81.414667 | V16: 82.8 | W16: ='DATA US'!I18 -> ARLEX FEBRI SURIANTO | X16: ='DATA US'!C18 -> 0134157802 | Y16: 141202510112056
A17: ='DATA US'!D79 -> BAGAS PRATAMA PUTRA | B17: ='DATA US'!B79 -> 222310063 | C17: Bekasi | D17: 27 November 2006 | E17: Teknik Dan Bisnis Sepeda Motor | F17: L | G17: 87.11 | H17: 84.3 | I17: 90.72 | J17: 88.08 | K17: 86 | L17: 90.72 | M17: 82 | N17: 85.5 | O17: 84.5 | P17: 80.5 | Q17: 85.5 | R17: 84.5 | S17: 82.5 | T17: 86.316667 | U17: 85.339833 | V17: 85.339833 | W17: ='DATA US'!I79 -> MISNA | X17: ='DATA US'!C79 -> 0062946213 | Y17: 141202510112079
A18: ='DATA US'!D51 -> CAESAR DANDI TRI PERKASA | B18: ='DATA US'!B51 -> 222310034 | C18: Bekasi | D18: 39176 | E18: Teknik Dan Bisnis Sepeda Motor | F18: L | G18: 84.1 | H18: 83.52 | I18: 88.8 | J18: 89.2 | K18: 85 | L18: 88.26 | M18: 82 | N18: 82.8 | O18: 81.5 | P18: 81 | Q18: 83 | R18: 84 | S18: 81.666667 | T18: 85.383333 | U18: 84.200667 | V18: 84.3 | W18: ='DATA US'!I51 -> LAMANSYAH ERWIN | X18: ='DATA US'!C51 -> 0077550363 | Y18: 141202510112091
A19: ='DATA US'!D19 -> DEDEN RIZKY SAPUTRA | B19: ='DATA US'!B19 -> 222310005 | C19: Bekasi | D19: 8 Agustus 2007 | E19: Teknik Dan Bisnis Sepeda Motor | F19: L | G19: 88.16 | H19: 88.02 | I19: 90.65 | J19: 91.64 | K19: 87.5 | L19: 90.3 | M19: 83 | N19: 85.2 | O19: 86 | P19: 84 | Q19: 86.5 | R19: 87 | S19: 85.333333 | T19: 86.875 | U19: 86.861833 | V19: 85.766667 | W19: ='DATA US'!I19 -> SANDIH | X19: ='DATA US'!C19 -> 0072858452 | Y19: 141202510112137
A20: ='DATA US'!D80 -> DEKA RAMADHANI | B20: ='DATA US'!B80 -> 222310064 | C20: Bekasi | D20: 29 Januari 2008 | E20: Teknik Dan Bisnis Sepeda Motor | F20: L | G20: 86.15 | H20: 85.4 | I20: 91.9 | J20: 90.68 | K20: 87 | L20: 92.84 | M20: 87 | N20: 84.5 | O20: 85.5 | P20: 82.5 | Q20: 86 | R20: 86 | S20: 84.5 | T20: 88.233333 | U20: 86.821833 | V20: 86.821833 | W20: ='DATA US'!I80 -> DEDE SUPENA | X20: ='DATA US'!C80 -> 0082368428 | Y20: 141202510112145
A21: ='DATA US'!D20 -> DENI RAHMAT SAPUTRA | B21: ='DATA US'!B20 -> 222310006 | C21: Bekasi | D21: 8 Agustus 2007 | E21: Teknik Dan Bisnis Sepeda Motor | F21: L | G21: 87.58 | H21: 87.94 | I21: 90.34 | J21: 92.56 | K21: 88 | L21: 90.36 | M21: 83.5 | N21: 81.9 | O21: 87 | P21: 83 | Q21: 86 | R21: 86 | S21: 83.833333 | T21: 86.858333 | U21: 86.437333 | V21: 85.633333 | W21: ='DATA US'!I20 -> SANDIH | X21: ='DATA US'!C20 -> 0073210618 | Y21: 141202510112151
A22: ='DATA US'!D52 -> DIMAS RIMUNANDAR | B22: ='DATA US'!B52 -> 222310035 | C22: Bekasi | D22: 13 April 2007 | E22: Teknik Dan Bisnis Sepeda Motor | F22: L | G22: 85.06 | H22: 84.58 | I22: 89.68 | J22: 82.32 | K22: 85 | L22: 85.52 | M22: 82 | N22: 86.5 | O22: 82.5 | P22: 79 | Q22: 82 | R22: 82 | S22: 82.166667 | T22: 86.475 | U22: 84.078 | V22: 83 | W22: ='DATA US'!I52 -> KAJI NURFAIDZI | X22: ='DATA US'!C52 -> 0074682824 | Y22: 141202510112167
A23: ='DATA US'!D53 -> DINAR RADITIYA PRATAMA | B23: ='DATA US'!B53 -> 222310036 | C23: Bekasi | D23: 20 Maret 2007 | E23: Teknik Dan Bisnis Sepeda Motor | F23: L | G23: 85.54 | H23: 83.88 | I23: 88.68 | J23: 87.38 | K23: 81 | L23: 85.52 | M23: 81.5 | N23: 86.9 | O23: 83 | P23: 79.5 | Q23: 82 | R23: 81.5 | S23: 78.833333 | T23: 83.6 | U23: 83.015 | V23: 83 | W23: ='DATA US'!I53 -> EKA RADIANSYAH | X23: ='DATA US'!C53 -> 0075646043 | Y23: 141202510112186
A24: ='DATA US'!D21 -> DITO AJI TRI CAHYO | B24: ='DATA US'!B21 -> 222310007 | C24: Bekasi | D24: 14 April 2007 | E24: Teknik Dan Bisnis Sepeda Motor | F24: L | G24: 82.82 | H24: 87.18 | I24: 89.31 | J24: 89.64 | K24: 85.5 | L24: 84.64 | M24: 84 | N24: 85.9 | O24: 85.5 | P24: 82 | Q24: 86 | R24: 85 | S24: 83.5 | T24: 84.183333 | U24: 84.9845 | V24: 84.966667 | W24: ='DATA US'!I21 -> BUANG SANTOSO (ALM) | X24: ='DATA US'!C21 -> 0072762394 | Y24: 141202510112197
A25: ='DATA US'!D81 -> DWIYAN PEBRIYANSYAH | B25: ='DATA US'!B81 -> 222310065 | C25: Bekasi | D25: 22 Februari 2007 | E25: Teknik Dan Bisnis Sepeda Motor | F25: L | G25: 84.75 | H25: 83.58 | I25: 86.66 | J25: 89.12 | K25: 86 | L25: 90.14 | M25: 82 | N25: 85 | O25: 83 | P25: 79.5 | Q25: 85 | R25: 85.5 | S25: 81 | T25: 85.033333 | U25: 84.384167 | V25: 84.384167 | W25: ='DATA US'!I81 -> WANTA | X25: ='DATA US'!C81 -> 0073890825 | Y25: 141202510112213
A26: ='DATA US'!D22 -> EGA MAULANA RAYHAN | B26: ='DATA US'!B22 -> 222310008 | C26: Bekasi | D26: 10 Januari 2007 | E26: Teknik Dan Bisnis Sepeda Motor | F26: L | G26: 83.04 | H26: 84.78 | I26: 88.06 | J26: 86.86 | K26: 81.5 | L26: 83.84 | M26: 80.5 | N26: 84.9 | O26: 82.5 | P26: 80 | Q26: 84 | R26: 82.5 | S26: 80.166667 | T26: 86.216667 | U26: 83.617333 | V26: 84.5 | W26: ='DATA US'!I22 -> NAMIN SUWANDA | X26: ='DATA US'!C22 -> 0078607611 | Y26: 141202510112236
A27: ='DATA US'!D54 -> FAHMI SABILA SIDKI | B27: ='DATA US'!B54 -> 222310037 | C27: Bekasi | D27: 27 Maret 2007 | E27: Teknik Dan Bisnis Sepeda Motor | F27: L | G27: 86.46 | H27: 83.68 | I27: 87.46 | J27: 90.56 | K27: 80.5 | L27: 82.32 | M27: 79 | N27: 86.4 | O27: 80 | P27: 77 | Q27: 81 | R27: 81.5 | S27: 77.166667 | T27: 83.466667 | U27: 82.185667 | V27: 82.466667 | W27: ='DATA US'!I54 -> TUIN | X27: ='DATA US'!C54 -> 0076987847 | Y27: 141202510112253
A28: ='DATA US'!D82 -> FALAH AZMI IBRAHIM | B28: ='DATA US'!B82 -> 222310066 | C28: Bekasi | D28: 10 Nopember 2005 | E28: Teknik Dan Bisnis Sepeda Motor | F28: L | G28: 87.04 | H28: 85.22 | I28: 88.88 | J28: 87.64 | K28: 83 | L28: 86.1 | M28: 83 | N28: 86.3 | O28: 81.5 | P28: 78.5 | Q28: 83.5 | R28: 84 | S28: 79.666667 | T28: 86.35 | U28: 84.167333 | V28: 84.167333 | W28: ='DATA US'!I82 -> HIDAYAT | X28: ='DATA US'!C82 -> 0053822774 | Y28: 141202510112269
A29: ='DATA US'!D83 -> FARHAN FIRMANSYAH | B29: ='DATA US'!B83 -> 222310067 | C29: Bekasi | D29: 22 Januari 2007 | E29: Teknik Dan Bisnis Sepeda Motor | F29: L | G29: 83.69 | H29: 84.52 | I29: 88.28 | J29: 86.52 | K29: 85 | L29: 86.06 | M29: 84 | N29: 85.6 | O29: 84 | P29: 79 | Q29: 84 | R29: 86 | S29: 81.166667 | T29: 85.725 | U29: 84.380167 | V29: 84.380167 | W29: ='DATA US'!I83 -> SIMAN | X29: ='DATA US'!C83 -> 007467363 | Y29: 141202510112274
A30: ='DATA US'!D23 -> FAUZA WIJAYA | B30: ='DATA US'!B23 -> 222310009 | C30: Bekasi | D30: 3 Juli 2007 | E30: Teknik Dan Bisnis Sepeda Motor | F30: L | G30: 84.36 | H30: 85.32 | I30: 88.98 | J30: 87.18 | K30: 85 | L30: 83.02 | M30: 80.5 | N30: 85.8 | O30: 82 | P30: 80.5 | Q30: 85.5 | R30: 85 | S30: 80.166667 | T30: 85.058333 | U30: 83.978 | V30: 85.666667 | W30: ='DATA US'!I23 -> MURKIM | X30: ='DATA US'!C23 -> 0071107397 | Y30: 141202510112284
A31: ='DATA US'!D24 -> FAZRI RAMDANI AL BASIT | B31: ='DATA US'!B24 -> 222310010 | C31: Bekasi | D31: 3 Oktober 2007 | E31: Teknik Dan Bisnis Sepeda Motor | F31: L | G31: 83.82 | H31: 84.18 | I31: 87.91 | J31: 85.9 | K31: 82.5 | L31: 84.46 | M31: 82 | N31: 85.6 | O31: 82 | P31: 81 | Q31: 85 | R31: 83.5 | S31: 79.5 | T31: 87.633333 | U31: 84.0835 | V31: 84.766667 | W31: ='DATA US'!I24 -> MUHAMAD SYARIF | X31: ='DATA US'!C24 -> 0072628439 | Y31: 141202510112299
A32: ='DATA US'!D55 -> FENDI LATIF HENANTA | B32: ='DATA US'!B55 -> 222310038 | C32: Bantul | D32: 29 Juli 2007 | E32: Teknik Dan Bisnis Sepeda Motor | F32: L | G32: 83.86 | H32: 85.34 | I32: 89.52 | J32: 81.78 | K32: 84.5 | L32: 85.68 | M32: 81.5 | N32: 83.2 | O32: 84 | P32: 80 | Q32: 84 | R32: 84.5 | S32: 80.5 | T32: 86.4 | U32: 83.962333 | V32: 84.266667 | W32: ='DATA US'!I55 -> AJI YULIANTO | X32: ='DATA US'!C55 -> 0076325232 | Y32: 141202510112318
A33: ='DATA US'!D56 -> FERDI LATIF HENANTA | B33: ='DATA US'!B56 -> 222310039 | C33: Bantul | D33: 29 Juli 2007 | E33: Teknik Dan Bisnis Sepeda Motor | F33: L | G33: 84.18 | H33: 86.4 | I33: 89.58 | J33: 81.32 | K33: 84.5 | L33: 91.16 | M33: 82.5 | N33: 83.6 | O33: 83.5 | P33: 81 | Q33: 83.5 | R33: 84.5 | S33: 81.333333 | T33: 87.983333 | U33: 84.847 | V33: 85.266667 | W33: ='DATA US'!I56 -> AJI YULIANTO | X33: ='DATA US'!C56 -> 0072890752 | Y33: 141202510112322
A34: ='DATA US'!D46 -> HAZAQ OSEAN RAFIF | B34: ='DATA US'!B46 -> 242512086 | C34: Majalengka | D34: 07 Februari 2007 | E34: Teknik Dan Bisnis Sepeda Motor | F34: L | G34: 85.76 | H34: 88.16 | I34: 88.44 | J34: 89.18 | K34: 81.5 | L34: 91.92 | M34: 77.5 | N34: 85.7 | O34: 75 | P34: 83 | Q34: 79.5 | R34: 80 | S34: 84.666667 | T34: 86.9 | U34: 84.676333 | V34: 86.266667 | W34: ='DATA US'!I46 -> Hendrik | X34: ='DATA US'!C46 -> 0075620652 | Y34: 141202510112359
A35: ='DATA US'!D84 -> IFNU MAULANA | B35: ='DATA US'!B84 -> 222310068 | C35: Magetan | D35: 7 Oktober 2007 | E35: Teknik Dan Bisnis Sepeda Motor | F35: L | G35: 85.63 | H35: 87.28 | I35: 91.76 | J35: 91.34 | K35: 85 | L35: 92.12 | M35: 87 | N35: 85.5 | O35: 86 | P35: 82.5 | Q35: 84.5 | R35: 85.5 | S35: 81.666667 | T35: 88.5 | U35: 86.4365 | V35: 86.4365 | W35: ='DATA US'!I84 -> GIYAT | X35: ='DATA US'!C84 -> 0076487037 | Y35: 141202510112382
A36: ='DATA US'!D25 -> INTO | B36: ='DATA US'!B25 -> 222310011 | C36: Bekasi | D36: 24 Februari 2006 | E36: Teknik Dan Bisnis Sepeda Motor | F36: L | G36: 83.12 | H36: 81.96 | I36: 86.32 | J36: 81.78 | K36: 78 | L36: 81.36 | M36: 79.5 | N36: 81.5 | O36: 80.5 | P36: 79 | Q36: 83 | R36: 83 | S36: 76 | T36: 82.966667 | U36: 81.240333 | V36: 84.4 | W36: ='DATA US'!I25 -> KARNO BIN EMUK | X36: ='DATA US'!C25 -> 0064029233 | Y36: 141202510112409
A37: ='DATA US'!D57 -> IPANG SAPUTRA | B37: ='DATA US'!B57 -> 222310040 | C37: Brebes | D37: 21 Desember 2006 | E37: Teknik Dan Bisnis Sepeda Motor | F37: L | G37: 82.88 | H37: 86.24 | I37: 88.84 | J37: 80.8 | K37: 83 | L37: 84.44 | M37: 81.5 | N37: 84.5 | O37: 84.5 | P37: 78 | Q37: 83 | R37: 83 | S37: 81.166667 | T37: 87.333333 | U37: 83.856667 | V37: 83.6 | W37: ='DATA US'!I57 -> WAWAN WIJAYA | X37: ='DATA US'!C57 -> 0065370722 | Y37: 141202510112415
A38: ='DATA US'!D26 -> IRPAN MAULANA | B38: ='DATA US'!B26 -> 222310012 | C38: Bekasi | D38: 19 Januari 2007 | E38: Teknik Dan Bisnis Sepeda Motor | F38: L | G38: 83.14 | H38: 83.74 | I38: 88.27 | J38: 81.78 | K38: 85.5 | L38: 82.1 | M38: 81 | N38: 85.2 | O38: 85.5 | P38: 81 | Q38: 85 | R38: 84.5 | S38: 80.333333 | T38: 85.958333 | U38: 83.804833 | V38: 84.533333 | W38: ='DATA US'!I26 -> SALIM | X38: ='DATA US'!C26 -> 0075073374 | Y38: 141202510112447
A39: ='DATA US'!D85 -> IRWAN SAPUTRA | B39: ='DATA US'!B85 -> 222310069 | C39: Bekasi | D39: 18 April 2007 | E39: Teknik Dan Bisnis Sepeda Motor | F39: L | G39: 82.95 | H39: 83.8 | I39: 86.58 | J39: 82.14 | K39: 84 | L39: 83.18 | M39: 84 | N39: 84.8 | O39: 81.5 | P39: 78.5 | Q39: 83.5 | R39: 84 | S39: 80.166667 | T39: 87.166667 | U39: 83.6275 | V39: 83.6275 | W39: ='DATA US'!I85 -> EDI | X39: ='DATA US'!C85 -> 0072650086 | Y39: 141202510112457
A40: ='DATA US'!D27 -> JULIUS MANGI ULY | B40: ='DATA US'!B27 -> 222310013 | C40: Bandung | D40: 23 Juni 2006 | E40: Teknik Dan Bisnis Sepeda Motor | F40: L | G40: 83.9 | H40: 87.12 | I40: 88.43 | J40: 90.26 | K40: 87 | L40: 84.84 | M40: 82 | N40: 84.7 | O40: 87 | P40: 82.5 | Q40: 86 | R40: 83.5 | S40: 83.5 | T40: 86.95 | U40: 85.545833 | V40: 85.366667 | W40: ='DATA US'!I27 -> YONAS MANGI ULY | X40: ='DATA US'!C27 -> 0066462669 | Y40: 141202510112462
...

Sheet ELIND
A1: NO | B1: No Surat | C1: NAMA SISWA | D1: NIS | E1: TEMPAT | F1: TANGGAL LAHIR | G1: Program Keahlian | H1: JK | I1: PAI | J1: PPKN | K1: Bhs. Indonesia | L1: Matematika | M1: Sejarah Indonesia | N1: Bhs. Inggris | O1: Seni Budaya | P1: PJOK | Q1: Bahasa Sunda | R1: SIMULASI DIGITAL | S1: FISIKA | T1: KIMIA | U1: Dasar Program | V1: Kompetensi Keahlian | W1: rata rata | X1: PKK | Y1: NAMA ORANG TUA | Z1: NISN | AA1: NOMER IJAZAH
C2: ='DATA US'!D158 -> 0 | Y2: ='DATA US'!I158 -> 0 | Z2: ='DATA US'!C158 -> 0
A3: 1 | C3: ='DATA US'!D129 -> ABI MAULANA CHANDRA | D3: ='DATA US'!B129 -> 222310110 | E3: ='DATA US'!F129 -> Bekasi | F3: ='DATA US'!G129 -> 20 November 2006 | G3: Teknik Elektronika Industri | H3: ='DATA US'!E129 -> L | I3: 86.51 | J3: 88.54 | K3: 90.76 | L3: 93.495 | M3: 88 | N3: 88.68 | O3: 85 | P3: 83.1 | Q3: 86 | R3: 84 | S3: 87.5 | T3: 87 | U3: 89.666667 | V3: 90.058667 | W3: 88.262143 | X3: 85.626667 | Y3: ='DATA US'!I129 -> CHANDRA | Z3: ='DATA US'!C129 -> 0064926120 | AA3: 141202510111878
A4: 2 | C4: ='DATA US'!D130 -> ADITYA AL MUJAKI | D4: ='DATA US'!B130 -> 222310111 | E4: ='DATA US'!F130 -> Bekasi | F4: ='DATA US'!G130 -> 11 November 2006 | G4: Teknik Elektronika Industri | H4: ='DATA US'!E130 -> L | I4: 84.94 | J4: 84.05 | K4: 87.88 | L4: 85.51 | M4: 84 | N4: 84.84 | O4: 81.5 | P4: 83.1 | Q4: 83.5 | R4: 79 | S4: 83 | T4: 83 | U4: 80.666667 | V4: 83.603333 | W4: 83.207302 | X4: 83.016667 | Y4: ='DATA US'!I130 -> SAMAN HERMAWAN | Z4: ='DATA US'!C130 -> 0061201721 | AA4: 141202510111901
A5: 3 | C5: ='DATA US'!D97 -> AMANDA DWI LESTARI | D5: ='DATA US'!B97 -> 222310080 | E5: ='DATA US'!F97 -> Bekasi | F5: ='DATA US'!G97 -> 19 Oktober 2007 | G5: Teknik Elektronika Industri | H5: ='DATA US'!E97 -> P | I5: 84.27 | J5: 84.64 | K5: 87.05 | L5: 90.455 | M5: 85 | N5: 86.13 | O5: 82 | P5: 81.9 | Q5: 82.5 | R5: 79.5 | S5: 84 | T5: 84 | U5: 85 | V5: 86.093333 | W5: 84.815119 | X5: 84.205833 | Y5: ='DATA US'!I97 -> INDA HERMAWAN | Z5: ='DATA US'!C97 -> 3070905598 | AA5: 141202510111953
A6: 4 | C6: ='DATA US'!D131 -> AMELIA | D6: ='DATA US'!B131 -> 222310113 | E6: ='DATA US'!F131 -> Bekasi | F6: ='DATA US'!G131 -> 1 Juli 2007 | G6: Teknik Elektronika Industri | H6: ='DATA US'!E131 -> P | I6: 83.5 | J6: 85.5 | K6: 86 | L6: 85.16 | M6: 84.5 | N6: 86.71 | O6: 80.5 | P6: 83.1 | Q6: 83 | R6: 79.5 | S6: 82 | T6: 81 | U6: 83 | V6: 82.834 | W6: 83.228492 | X6: 84.158333 | Y6: ='DATA US'!I131 -> NIAN | Z6: ='DATA US'!C131 -> 0073563861 | AA6: 141202510111962
A7: 5 | C7: ='DATA US'!D98 -> ANA AZIZAH | D7: ='DATA US'!B98 -> 222310081 | E7: ='DATA US'!F98 -> Bekasi | F7: ='DATA US'!G98 -> 12 Desember 2007 | G7: Teknik Elektronika Industri | H7: ='DATA US'!E98 -> P | I7: 84.3 | J7: 83.52 | K7: 87.12 | L7: 89.725 | M7: 86 | N7: 87.68 | O7: 82.5 | P7: 82.4 | Q7: 82.5 | R7: 78.5 | S7: 84 | T7: 83 | U7: 83 | V7: 86.349333 | W7: 84.62504 | X7: 85.134167 | Y7: ='DATA US'!I98 -> SAANIN | Z7: ='DATA US'!C98 -> 0074408442 | AA7: 141202510111982
A8: 6 | C8: ='DATA US'!D132 -> AQILA QEISHA RAHMADANI | D8: ='DATA US'!B132 -> 222310114 | E8: ='DATA US'!F132 -> Bekasi | F8: ='DATA US'!G132 -> 29 September 2007 | G8: Teknik Elektronika Industri | H8: ='DATA US'!E132 -> P | I8: 84.48 | J8: 85.4 | K8: 87.1 | L8: 85.39 | M8: 85 | N8: 82.5 | O8: 81.5 | P8: 83.1 | Q8: 85 | R8: 79 | S8: 81.5 | T8: 81 | U8: 83.833333 | V8: 83.090667 | W8: 83.351984 | X8: 82.468333 | Y8: ='DATA US'!I132 -> AHMAD BAEHAQI | Z8: ='DATA US'!C132 -> 0072459941 | AA8: 141202510112018
A9: 7 | C9: ='DATA US'!D133 -> AYU PUTRI NEGARI | D9: ='DATA US'!B133 -> 222310115 | E9: ='DATA US'!F133 -> Bekasi | F9: ='DATA US'!G133 -> 18 September 2008 | G9: Teknik Elektronika Industri | H9: ='DATA US'!E133 -> P | I9: 84.04 | J9: 85.9 | K9: 86.4 | L9: 82.595 | M9: 84.5 | N9: 88.42 | O9: 81 | P9: 83.1 | Q9: 84 | R9: 79.5 | S9: 81.5 | T9: 81 | U9: 83.833333 | V9: 83.128667 | W9: 83.420635 | X9: 82.735 | Y9: ='DATA US'!I133 -> MARZUKIH | Z9: ='DATA US'!C133 -> 0064002542 | AA9: 141202510112061
A10: 8 | C10: ='DATA US'!D99 -> BANU BUKHORI | D10: ='DATA US'!B99 -> 222310082 | E10: ='DATA US'!F99 -> Bekasi | F10: ='DATA US'!G99 -> 5 Februari 2007 | G10: Teknik Elektronika Industri | H10: ='DATA US'!E99 -> P | I10: 86.38 | J10: 86.3 | K10: 90.1 | L10: 89.585 | M10: 88 | N10: 91.82 | O10: 83.5 | P10: 88.6 | Q10: 85 | R10: 83.5 | S10: 83.5 | T10: 83.5 | U10: 83.666667 | V10: 86.656 | W10: 86.198254 | X10: 86.098333 | Y10: ='DATA US'!I99 -> MARYONO | Z10: ='DATA US'!C99 -> 0079089656 | AA10: 141202510112087
A11: 9 | C11: ='DATA US'!D134 -> DAFA ADITYA PUTRA | D11: ='DATA US'!B134 -> 222310116 | E11: ='DATA US'!F134 -> Bekasi | F11: ='DATA US'!G134 -> 31 Oktober 2007 | G11: Teknik Elektronika Industri | H11: ='DATA US'!E134 -> L | I11: 85.51 | J11: 85.64 | K11: 89.82 | L11: 91.67 | M11: 87.5 | N11: 88.08 | O11: 82.5 | P11: 83.1 | Q11: 84.5 | R11: 80.5 | S11: 82.5 | T11: 83 | U11: 88 | V11: 87.505333 | W11: 86.215159 | X11: 84.671667 | Y11: ='DATA US'!I134 -> NAMUN | Z11: ='DATA US'!C134 -> 0073240741 | AA11: 141202510112107
A12: 10 | C12: ='DATA US'!D100 -> DAMA AJI | D12: ='DATA US'!B100 -> 222310083 | E12: ='DATA US'!F100 -> Jakarta | F12: ='DATA US'!G100 -> 39024 | G12: Teknik Elektronika Industri | H12: ='DATA US'!E100 -> L | I12: 84.91 | J12: 84.38 | K12: 85.98 | L12: 89.625 | M12: 84.5 | N12: 77.38 | O12: 85 | P12: 83.8 | Q12: 84 | R12: 80 | S12: 82.5 | T12: 82 | U12: 82.5 | V12: 85.234667 | W12: 83.917421 | X12: 84.5175 | Y12: ='DATA US'!I100 -> SURAHMAN | Z12: ='DATA US'!C100 -> 0065044881 | AA12: 141202510112115
A13: 11 | C13: ='DATA US'!D101 -> DAVINA KEISYAH PUTRI | D13: ='DATA US'!B101 -> 222310084 | E13: ='DATA US'!F101 -> Bekasi | F13: ='DATA US'!G101 -> 27 Maret 2007 | G13: Teknik Elektronika Industri | H13: ='DATA US'!E101 -> P | I13: 86.11 | J13: 85.88 | K13: 87.68 | L13: 91.255 | M13: 86 | N13: 87.08 | O13: 82 | P13: 82.2 | Q13: 86 | R13: 80.5 | S13: 84.5 | T13: 84.5 | U13: 84.333333 | V13: 85.846667 | W13: 85.256071 | X13: 84.439167 | Y13: ='DATA US'!I101 -> DEDY MULYADI | Z13: ='DATA US'!C101 -> 0074594754 | AA13: 141202510112129
A14: 12 | C14: ='DATA US'!D102 -> DINA SUBARKAH | D14: ='DATA US'!B102 -> 222310085 | E14: ='DATA US'!F102 -> Bekasi | F14: ='DATA US'!G102 -> 4 Maret 2007 | G14: Teknik Elektronika Industri | H14: ='DATA US'!E102 -> P | I14: 84.67 | J14: 84.38 | K14: 88.78 | L14: 90.235 | M14: 87.5 | N14: 88.62 | O14: 83 | P14: 85.7 | Q14: 85.5 | R14: 80.5 | S14: 83.5 | T14: 83.5 | U14: 84.833333 | V14: 86.237333 | W14: 85.519127 | X14: 84.33 | Y14: ='DATA US'!I102 -> EDI SUBARKAH | Z14: ='DATA US'!C102 -> 0071365415 | AA14: 141202510112171
A15: 13 | C15: ='DATA US'!D128 -> DWI ARIFANI ADZANA | D15: ='DATA US'!B128 -> 242512087 | E15: ='DATA US'!F128 -> Bekasi | F15: ='DATA US'!G128 -> 19 Mei 2006 | G15: Teknik Elektronika Industri | H15: ='DATA US'!E128 -> L | I15: 82.7 | J15: 82.32 | K15: 85.55 | L15: 90.51 | M15: 85 | N15: 84.5 | O15: 80.5 | P15: 86.5 | Q15: 81 | R15: 78 | S15: 82 | T15: 83 | U15: 78.666667 | V15: 83.822 | W15: 82.883532 | X15: 83.864167 | Y15: ='DATA US'!I128 -> ARMAN | Z15: ='DATA US'!C128 -> 0066035802 | AA15: 141202510112207
A16: 14 | C16: ='DATA US'!D135 -> ECY LAURA CITRA | D16: ='DATA US'!B135 -> 222310117 | E16: ='DATA US'!F135 -> Subang | F16: ='DATA US'!G135 -> 4 Juli 2007 | G16: Teknik Elektronika Industri | H16: ='DATA US'!E135 -> P | I16: 83.38 | J16: 85.14 | K16: 86.59 | L16: 82.88 | M16: 83.5 | N16: 83.98 | O16: 81 | P16: 83.1 | Q16: 83 | R16: 79.5 | S16: 83.5 | T16: 84 | U16: 83.833333 | V16: 83.843333 | W16: 83.469286 | X16: 82.568333 | Y16: ='DATA US'!I135 -> BUSTAMI CHANIAGO | Z16: ='DATA US'!C135 -> 0074172506 | AA16: 141202510112226
A17: 15 | C17: ='DATA US'!D103 -> ERWIN MAULANA | D17: ='DATA US'!B103 -> 222310086 | E17: ='DATA US'!F103 -> Bekasi | F17: ='DATA US'!G103 -> 12 Mei 2006 | G17: Teknik Elektronika Industri | H17: ='DATA US'!E103 -> L | I17: 84.49 | J17: 84.36 | K17: 88.42 | L17: 92.455 | M17: 84.5 | N17: 88.65 | O17: 82.5 | P17: 88.5 | Q17: 84 | R17: 80.5 | S17: 83.5 | T17: 84 | U17: 84.833333 | V17: 84.706 | W17: 85.20254 | X17: 85.348333 | Y17: ='DATA US'!I103 -> MAMAN FIRMANSYAH | Z17: ='DATA US'!C103 -> 0061047101 | AA17: 141202510112245
A18: 16 | C18: ='DATA US'!D136 -> FEBRY LIDIYANA MULYA PUTRI SURYANA | D18: ='DATA US'!B136 -> 222310118 | E18: ='DATA US'!F136 -> Jakarta | F18: ='DATA US'!G136 -> 6 Februari 2007 | G18: Teknik Elektronika Industri | H18: ='DATA US'!E136 -> P | I18: 82.82 | J18: 85.68 | K18: 85.5 | L18: 82.2 | M18: 83.5 | N18: 83.58 | O18: 80.5 | P18: 83.1 | Q18: 85.5 | R18: 78.5 | S18: 84 | T18: 84 | U18: 82.5 | V18: 82.937333 | W18: 83.034524 | X18: 82.658333 | Y18: ='DATA US'!I136 -> UJANG YANA SURYANA | Z18: ='DATA US'!C136 -> 0078208166 | AA18: 141202510112303
A19: 17 | C19: ='DATA US'!D137 -> FINITA MEYDINAYATI | D19: ='DATA US'!B137 -> 222310119 | E19: ='DATA US'!F137 -> Bekasi | F19: ='DATA US'!G137 -> 13 Mei 2007 | G19: Teknik Elektronika Industri | H19: ='DATA US'!E137 -> P | I19: 85.61 | J19: 84.85 | K19: 87.46 | L19: 83.21 | M19: 85 | N19: 88.86 | O19: 81.5 | P19: 83.1 | Q19: 84.5 | R19: 80 | S19: 84 | T19: 84 | U19: 83.5 | V19: 85.89 | W19: 84.622937 | X19: 85.041667 | Y19: ='DATA US'!I137 -> DIDIN | Z19: ='DATA US'!C137 -> 0076209344 | AA19: 141202510112332
A20: 18 | C20: ='DATA US'!D104 -> GITA AMELIA | D20: ='DATA US'!B104 -> 222310087 | E20: ='DATA US'!F104 -> Bekasi | F20: ='DATA US'!G104 -> 11 Mei 2006 | G20: Teknik Elektronika Industri | H20: ='DATA US'!E104 -> P | I20: 84.14 | J20: 83.54 | K20: 87.58 | L20: 90.19 | M20: 86.5 | N20: 84.76 | O20: 84 | P20: 83.1 | Q20: 83.5 | R20: 81 | S20: 82.5 | T20: 83.5 | U20: 83.666667 | V20: 85.622667 | W20: 84.641548 | X20: 84.049167 | Y20: ='DATA US'!I104 -> SALIM | Z20: ='DATA US'!C104 -> 0061823698 | AA20: 141202510112342
A21: 19 | C21: ='DATA US'!D138 -> HERMAWAN | D21: ='DATA US'!B138 -> 222310120 | E21: ='DATA US'!F138 -> Jakarta | F21: ='DATA US'!G138 -> 12 Agustus 2007 | G21: Teknik Elektronika Industri | H21: ='DATA US'!E138 -> L | I21: 84.26 | J21: 82.44 | K21: 88.97 | L21: 82.06 | M21: 86 | N21: 90.07 | O21: 82.5 | P21: 83.1 | Q21: 83.5 | R21: 82 | S21: 83.5 | T21: 84 | U21: 85.166667 | V21: 84.375333 | W21: 84.42873 | X21: 83.226667 | Y21: ='DATA US'!I138 -> HERMANTO | Z21: ='DATA US'!C138 -> 0073458110 | AA21: 141202510112361
A22: 20 | C22: ='DATA US'!D139 -> HIJIYAH BULAN DARI | D22: ='DATA US'!B139 -> 222310121 | E22: ='DATA US'!F139 -> Bekasi | F22: ='DATA US'!G139 -> 1 Januari 2007 | G22: Teknik Elektronika Industri | H22: ='DATA US'!E139 -> P | I22: 85.26 | J22: 84.51 | K22: 86.96 | L22: 81.995 | M22: 84.5 | N22: 91.5 | O22: 81.5 | P22: 83.1 | Q22: 83 | R22: 81 | S22: 83 | T22: 84 | U22: 86.666667 | V22: 86.402667 | W22: 85.058254 | X22: 83.885 | Y22: ='DATA US'!I139 -> HENDRA PERMANA | Z22: ='DATA US'!C139 -> 0075502511 | AA22: 141202510112377
A23: 21 | C23: ='DATA US'!D105 -> IMAS RAHAYU | D23: ='DATA US'!B105 -> 222310088 | E23: ='DATA US'!F105 -> Bekasi | F23: ='DATA US'!G105 -> 28 Desember 2006 | G23: Teknik Elektronika Industri | H23: ='DATA US'!E105 -> P | I23: 85.7 | J23: 84.6 | K23: 89.72 | L23: 91.015 | M23: 85 | N23: 86.96 | O23: 83 | P23: 85.6 | Q23: 85 | R23: 80.5 | S23: 84.5 | T23: 84.5 | U23: 86.5 | V23: 86.208 | W23: 85.770238 | X23: 84.54 | Y23: ='DATA US'!I105 -> MISKA | Z23: ='DATA US'!C105 -> 3066812278 | AA23: 141202510112397
A24: 22 | C24: ='DATA US'!D140 -> IRFA MUBAROK | D24: ='DATA US'!B140 -> 222310122 | E24: ='DATA US'!F140 -> Bekasi | F24: ='DATA US'!G140 -> 31 Mei 2006 | G24: Teknik Elektronika Industri | H24: ='DATA US'!E140 -> L | I24: 84.29 | J24: 84.66 | K24: 88.46 | L24: 89.305 | M24: 85 | N24: 82.72 | O24: 82.5 | P24: 83.1 | Q24: 84.5 | R24: 81.5 | S24: 84 | T24: 83 | U24: 86.333333 | V24: 84.123333 | W24: 84.697698 | X24: 86 | Y24: ='DATA US'!I140 -> MASKON BIN ZAZULI | Z24: ='DATA US'!C140 -> 0064458927 | AA24: 141202510112427
A25: 23 | C25: ='DATA US'!D141 -> IRMA ELITANA | D25: ='DATA US'!B141 -> 222310123 | E25: ='DATA US'!F141 -> Bekasi | F25: ='DATA US'!G141 -> 6 Juni 2005 | G25: Teknik Elektronika Industri | H25: ='DATA US'!E141 -> P | I25: 84.38 | J25: 86.52 | K25: 86.94 | L25: 85.985 | M25: 86.5 | N25: 86.09 | O25: 81 | P25: 83.1 | Q25: 85 | R25: 81.5 | S25: 85.5 | T25: 85 | U25: 87 | V25: 85.487333 | W25: 85.28381 | X25: 85.008333 | Y25: ='DATA US'!I141 -> DAHLAN BIN ENDING | Z25: ='DATA US'!C141 -> 0065646956 | AA25: 141202510112433
A26: 24 | C26: ='DATA US'!D106 -> KAILA ZAHRA | D26: ='DATA US'!B106 -> 222310089 | E26: ='DATA US'!F106 -> Bekasi | F26: ='DATA US'!G106 -> 13 Januari 2007 | G26: Teknik Elektronika Industri | H26: ='DATA US'!E106 -> P | I26: 84.41 | J26: 84 | K26: 88.23 | L26: 89.81 | M26: 85 | N26: 83.8 | O26: 86.5 | P26: 88 | Q26: 84.5 | R26: 84 | S26: 84.5 | T26: 84 | U26: 84.666667 | V26: 87.525333 | W26: 85.853968 | X26: 84.556667 | Y26: ='DATA US'!I106 -> RAHMAT TULOH HIDAYAT | Z26: ='DATA US'!C106 -> 0073712406 | AA26: 141202510112477
A27: 25 | C27: ='DATA US'!D107 -> KHEYSA VIDA ANGGRAINI | D27: ='DATA US'!B107 -> 222310090 | E27: ='DATA US'!F107 -> Sukoharjo | F27: ='DATA US'!G107 -> 8 Maret 2007 | G27: Teknik Elektronika Industri | H27: ='DATA US'!E107 -> P | I27: 83.93 | J27: 83.12 | K27: 86.2 | L27: 90.495 | M27: 81.5 | N27: 85.81 | O27: 83 | P27: 85.8 | Q27: 82.5 | R27: 81 | S27: 83.5 | T27: 83 | U27: 81.833333 | V27: 85.060667 | W27: 84.028452 | X27: 83.939167 | Y27: ='DATA US'!I107 -> FAJAR AMIR FAHMI | Z27: ='DATA US'!C107 -> 0073407455 | AA27: 141202510112491
A28: 26 | C28: ='DATA US'!D108 -> LEO STEPEN | D28: ='DATA US'!B108 -> 222310091 | E28: ='DATA US'!F108 -> Bekasi | F28: ='DATA US'!G108 -> 26 Desember 2005 | G28: Teknik Elektronika Industri | H28: ='DATA US'!E108 -> L | I28: 85.93 | J28: 85.6 | K28: 85.82 | L28: 80.81 | M28: 86.5 | N28: 84.76 | O28: 83.5 | P28: 86.7 | Q28: 85.5 | R28: 79.5 | S28: 84 | T28: 84 | U28: 82.666667 | V28: 56.064 | W28: 77.473333 | X28: 86 | Y28: ='DATA US'!I108 -> NURMIN | Z28: ='DATA US'!C108 -> 0058876158 | AA28: 141202510112506
A29: 27 | C29: ='DATA US'!D142 -> LUFI RAMADHANI | D29: ='DATA US'!B142 -> 222310124 | E29: ='DATA US'!F142 -> Bekasi | F29: ='DATA US'!G142 -> 18 Oktober 2006 | G29: Teknik Elektronika Industri | H29: ='DATA US'!E142 -> L | I29: 86.12 | J29: 87.1 | K29: 88.63 | L29: 86.375 | M29: 87 | N29: 87.93 | O29: 84 | P29: 83.1 | Q29: 87 | R29: 83 | S29: 84 | T29: 83 | U29: 89 | V29: 87.374 | W29: 86.448095 | X29: 84.285 | Y29: ='DATA US'!I142 -> ABDUL KARIM | Z29: ='DATA US'!C142 -> 0061468832 | AA29: 141202510112514
A30: 28 | C30: ='DATA US'!D109 -> M. FACHRI RIZKI MAULANA | D30: ='DATA US'!B109 -> 222310092 | E30: ='DATA US'!F109 -> Bekasi | F30: ='DATA US'!G109 -> 27 Agustus 2007 | G30: Teknik Elektronika Industri | H30: ='DATA US'!E109 -> L | I30: 89.12 | J30: 88.6 | K30: 91.74 | L30: 91.855 | M30: 88 | N30: 92.92 | O30: 84 | P30: 88.8 | Q30: 88.5 | R30: 84 | S30: 84.5 | T30: 84 | U30: 85.333333 | V30: 86.847333 | W30: 87.250476 | X30: 85.988333 | Y30: ='DATA US'!I109 -> MAKMUN | Z30: ='DATA US'!C109 -> 0079452159 | AA30: 141202510112556
A31: 29 | C31: ='DATA US'!D143 -> M. REUBEN ARFAQI AGUSTIAN | D31: ='DATA US'!B143 -> 222310129 | E31: ='DATA US'!F143 -> Bekasi | F31: ='DATA US'!G143 -> 1 Agustus 2007 | G31: Teknik Elektronika Industri | H31: ='DATA US'!E143 -> L | I31: 84.43 | J31: 83.99 | K31: 89.1 | L31: 89.185 | M31: 85 | N31: 87.61 | O31: 83 | P31: 84.3 | Q31: 84.5 | R31: 80.5 | S31: 84 | T31: 84 | U31: 85.833333 | V31: 85.587333 | W31: 85.143651 | X31: 82.965 | Y31: ='DATA US'!I143 -> SUHANA | Z31: ='DATA US'!C143 -> 0077314727 | AA31: 141202510112561
A32: 30 | C32: ='DATA US'!D145 -> MARYATI | D32: ='DATA US'!B145 -> 222310125 | E32: ='DATA US'!F145 -> Bekasi | F32: ='DATA US'!G145 -> 23 Desember 2006 | G32: Teknik Elektronika Industri | H32: ='DATA US'!E145 -> P | I32: 83.24 | J32: 82.44 | K32: 87.87 | L32: 82.135 | M32: 84.5 | N32: 85.08 | O32: 80.5 | P32: 84 | Q32: 83 | R32: 80.5 | S32: 83 | T32: 84 | U32: 83.5 | V32: 85.296667 | W32: 83.86 | X32: 83.9 | Y32: ='DATA US'!I145 -> CATIM | Z32: ='DATA US'!C145 -> 0067588196 | AA32: 141202510112625
A33: 31 | C33: ='DATA US'!D146 -> MEISYA DITA KHOIRUNISA | D33: ='DATA US'!B146 -> 222310126 | E33: ='DATA US'!F146 -> Bekasi | F33: ='DATA US'!G146 -> 1 Mei 2006 | G33: Teknik Elektronika Industri | H33: ='DATA US'!E146 -> P | I33: 84.54 | J33: 85.78 | K33: 86.62 | L33: 82.38 | M33: 84.5 | N33: 84.56 | O33: 82 | P33: 83.9 | Q33: 82.5 | R33: 80.5 | S33: 84 | T33: 84 | U33: 86.5 | V33: 83.948667 | W33: 84.208413 | X33: 83.853333 | Y33: ='DATA US'!I146 -> BO'AN | Z33: ='DATA US'!C146 -> 0062811006 | AA33: 141202510112637
A34: 32 | C34: ='DATA US'!D147 -> MELA MELATI | D34: ='DATA US'!B147 -> 222310127 | E34: ='DATA US'!F147 -> Bekasi | F34: ='DATA US'!G147 -> 2 Juli 2007 | G34: Teknik Elektronika Industri | H34: ='DATA US'!E147 -> P | I34: 83.78 | J34: 84.9 | K34: 88.66 | L34: 84.395 | M34: 85 | N34: 84.81 | O34: 81 | P34: 84.4 | Q34: 84 | R34: 79.5 | S34: 84 | T34: 84 | U34: 87.333333 | V34: 83.732667 | W34: 84.439841 | X34: 84.128333 | Y34: ='DATA US'!I147 -> NABRIH | Z34: ='DATA US'!C147 -> 0079477598 | AA34: 141202510112644
A35: 33 | C35: ='DATA US'!D110 -> MELI ANJANI | D35: ='DATA US'!B110 -> 222310093 | E35: ='DATA US'!F110 -> Bekasi | F35: ='DATA US'!G110 -> 3 Juni 2007 | G35: Teknik Elektronika Industri | H35: ='DATA US'!E110 -> P | I35: 84.3 | J35: 83.56 | K35: 88.54 | L35: 89.685 | M35: 85 | N35: 82.12 | O35: 84 | P35: 88.1 | Q35: 83 | R35: 82.5 | S35: 83 | T35: 82 | U35: 83.666667 | V35: 86.54 | W35: 84.953095 | X35: 84.51 | Y35: ='DATA US'!I110 -> OMA | Z35: ='DATA US'!C110 -> 0071002555 | AA35: 141202510112658
A36: 34 | C36: ='DATA US'!D111 -> MILDA APRILIANNI | D36: ='DATA US'!B111 -> 222310094 | E36: ='DATA US'!F111 -> Sukabumi | F36: ='DATA US'!G111 -> 18 April 2006 | G36: Teknik Elektronika Industri | H36: ='DATA US'!E111 -> P | I36: 85.44 | J36: 84.94 | K36: 89.57 | L36: 90.955 | M36: 86.5 | N36: 92.26 | O36: 84 | P36: 81.8 | Q36: 86 | R36: 82 | S36: 84.5 | T36: 83 | U36: 85.666667 | V36: 85.388 | W36: 85.647341 | X36: 83.689167 | Y36: ='DATA US'!I111 -> DADANG SUHENDI | Z36: ='DATA US'!C111 -> 0067648631 | AA36: 141202510112661
A37: 35 | C37: ='DATA US'!D112 -> MUHAMAD RISQI FAJRI | D37: ='DATA US'!B112 -> 222310095 | E37: ='DATA US'!F112 -> Bekasi | F37: ='DATA US'!G112 -> 39202 | G37: Teknik Elektronika Industri | H37: ='DATA US'!E112 -> L | I37: 88.44 | J37: 87.32 | K37: 88.89 | L37: 93.03 | M37: 87.5 | N37: 87.43 | O37: 84 | P37: 88 | Q37: 87 | R37: 83 | S37: 87.5 | T37: 87 | U37: 87.166667 | V37: 85.605333 | W37: 86.77127 | X37: 83.56 | Y37: ='DATA US'!I112 -> SUPARNO | Z37: ='DATA US'!C112 -> 0077749659 | AA37: 141202510112728
A38: 36 | C38: ='DATA US'!D148 -> MUHAMMAD ALBANI FAHREZI | D38: ='DATA US'!B148 -> 222310128 | E38: ='DATA US'!F148 -> Bekasi | F38: ='DATA US'!G148 -> 30 Januari 2007 | G38: Teknik Elektronika Industri | H38: ='DATA US'!E148 -> L | I38: 84.9875 | J38: 83.72 | K38: 88.08 | L38: 84.085 | M38: 83.5 | N38: 87.13 | O38: 80.5 | P38: 84 | Q38: 85 | R38: 81.5 | S38: 84 | T38: 83 | U38: 79.666667 | V38: 84.727333 | W38: 83.573452 | X38: 82.903333 | Y38: ='DATA US'!I148 -> MARSUDI | Z38: ='DATA US'!C148 -> 0076891945 | AA38: 141202510112742
A39: 37 | C39: ='DATA US'!D113 -> MUHAMMAD KHOLIFI ILHAM | D39: ='DATA US'!B113 -> 222310096 | E39: ='DATA US'!F113 -> Bekasi | F39: ='DATA US'!G113 -> 6 Maret 2007 | G39: Teknik Elektronika Industri | H39: ='DATA US'!E113 -> L | I39: 85.38 | J39: 85.36 | K39: 89.46 | L39: 90.535 | M39: 87 | N39: 85.9 | O39: 83 | P39: 87.3 | Q39: 87 | R39: 82.5 | S39: 85 | T39: 85.5 | U39: 85.5 | V39: 87.368 | W39: 85.19869 | X39: 61.8975 | Y39: ='DATA US'!I113 -> NIAN | Z39: ='DATA US'!C113 -> 0071561555 | AA39: 141202510112785
A40: 38 | C40: ='DATA US'!D144 -> MUHAMMAD TAUPIQ NUR SALEH | D40: ='DATA US'!B144 -> 222310130 | E40: ='DATA US'!F144 -> Bekasi | F40: ='DATA US'!G144 -> 23 Oktober 2007 | G40: Teknik Elektronika Industri | H40: ='DATA US'!E144 -> L | I40: 84.1 | J40: 86.04 | K40: 85.17 | L40: 85.04 | M40: 84.5 | N40: 87.67 | O40: 81 | P40: 83.8 | Q40: 85 | R40: 81 | S40: 84 | T40: 84 | U40: 87 | V40: 82.984667 | W40: 84.288968 | X40: 82.825 | Y40: ='DATA US'!I144 -> NURDIAN | Z40: ='DATA US'!C144 -> 0078743168 | AA40: 141202510112833
...

Sheet TRANSKRIF TSM
A1: No | B1: NIS | C1: TEMAPAT | D1: TANGGAL LAHIR | E1: NISN | F1: Nama | G1: PAI 1 | H1: PAI 2 | I1: PAI 3 | J1: PAI 4 | K1: PAI 5 | L1: PAI 6 | M1: PKN 1 | N1: PKN 2 | O1: PKN 3 | P1: PKN 4 | Q1: PKN 5 | R1: PKN 6 | S1: BHS.IND 1 | T1: BHS.IND 2 | U1: BHS.IND 3 | V1: BHS.IND 4 | W1: BHS.IND 5 | X1: BHS.IND 6 | Y1: MTK 1 | Z1: MTK 2 | AA1: MTK 3 | AB1: MTK 4 | AC1: MTK 5 | AD1: MTK 6 | AE1: ENGLISH 1 | AF1: ENGLISH 2 | AG1: ENGLISH 3 | AH1: ENGLISH 4 | AI1: ENGLISH 5 | AJ1: ENGLISH 6 | AK1: SEJARAH.INDO 1 | AL1: SEJARAH.INDO 2 | AM1: SEJARAH.INDO 3 | AN1: SEJARAH.INDO 4 | AO1: SEJARAH.INDO 5 | AP1: SEJARAH.INDO 6 | AQ1: SENI BUDAYA 1 | AR1: SENI BUDAYA 2 | AS1: PJOK1 | AT1: PJOK2 | AU1: PJOK3 | AV1: PJOK4 | AW1: SIMDIG 1 | AX1: SIMDIG 2 | AY1: FISIKA 1 | AZ1: FISIKA 2 | BA1: KIMIA 1 | BB1: KIMIA 2 | BC1: GT0 1 | BD1: GT0 2 | BE1: TDO 1 | BF1: TDO 2 | BG1: PDTO 1 | BH1: PDTO 2 | BI1: PMSM 3 | BJ1: PMSM 4 | BK1: PMSM 5 | BL1: PMSM 6 | BM1: PSSM 3 | BN1: PSSM 4 | BO1: PSSM 5 | BP1: PSSM 6 | BQ1: PLSM 3 | BR1: PLSM 4 | BS1: PLSM 5 | BT1: PLSM 6 | BU1: PBSM 5 | BV1: PBSM 6 | BW1: PKK 3 | BX1: PKK 4 | BY1: PKK 5 | BZ1: PKK 6 | CA1: BHS.Sunda 1 | CB1: BHS.Sunda 2 | CC1: TEMPAT PKL 1 | CD1: ALAMAT PKL 1 | CE1: RENTANG WAKTU 1 | CF1: NILAI PKL | CG1: TEMPAT PKL 1 | CH1: ALAMAT PKL 1 | CI1: RENTANG WAKTU 1 | CJ1: NILAI PKL 2 | CK1: PRAKTEK BHS.INDO | CL1: PRAKTEK PAI | CM1: PRAKTEK BHS.INGGRIS | CN1: PRAKTEK PJOK | CO1: PRAKTEK UKK | CP1: UJIKOM | CQ1: NILAI RATA RATA PAI | CR1: RATA-RATA PKN | CS1: RATA-RATA BHS.MTK | CT1: RATA-RATA BHS.INDO | CU1: RATA-RATA BHS.INGGRIS | CV1: RATA-RATA SENI BUDAYA | CW1: RATA PJOK | CX1: RATA BHS.SUNDA | CY1: RATA KIMIA | CZ1: RATA FISIKA | DA1: RATA SIMDIG | DB1: RATA TDO | DC1: RATA PDTO | DD1: RATA GTO | DE1: RATA MESIN | DF1: RATA SASIS | DG1: RATA LISTRIK | DH1: RATA PKK | DI1: RATA PBSM | DJ1: RATA SEJARAH INDO | DK1: RATA TOTAL
A2: 1 | B2: ='DATA US'!B15 -> 222310001 | C2: ='DATA US'!F15 -> BEKASI | D2: ='DATA US'!G15 -> 23 April 2007 | E2: ='DATA US'!C15 -> 0072124779 | F2: ='DATA US'!D15 -> ADAM ZAKIE RAMADHAN | G2: 82 | H2: 82 | I2: 86 | J2: 84 | K2: 84 | L2: 85 | M2: 83 | N2: 84 | O2: 81 | P2: 83 | Q2: 84 | R2: 86 | S2: 84 | T2: 85 | U2: 89 | V2: 92 | W2: 90 | X2: 89 | Y2: 75 | Z2: 75 | AA2: 86 | AB2: 86 | AC2: 82 | AD2: 90 | AE2: 82 | AF2: 78 | AG2: 79 | AH2: 84 | AI2: 90 | AJ2: 90 | AK2: 85 | AL2: 85 | AM2: - | AN2: - | AO2: - | AP2: - | AQ2: 83 | AR2: 80 | AS2: 80 | AT2: 83 | AU2: 82 | AV2: 82 | AW2: 80 | AX2: 81 | AY2: 86 | AZ2: 86 | BA2: 83 | BB2: 84 | BC2: 83 | BD2: 83 | BE2: 83 | BF2: 82 | BG2: 75 | BH2: 76 | BI2: 79 | BJ2: 79 | BK2: 84 | BL2: 86 | BM2: 87 | BN2: 85 | BO2: 85 | BP2: 86 | BQ2: 83 | BR2: 82 | BS2: 86 | BT2: 86 | BU2: 85 | BV2: 89 | BW2: 87 | BX2: 87 | BY2: 86 | BZ2: 89 | CA2: 83 | CB2: 86 | CC2: PT. Mitsuba Indonesia | CD2: Kawasan Industri MM2100 Jatiwangi Bekasi | CE2: 06 Mei 2024 - 02 Agt 2024 | CF2: B | CK2: 91.666667 | CL2: 86 | CM2: 84 | CN2: 87 | CO2: 83 | CP2: 89 | CQ2: =AVERAGE(G2:L2) -> 83.833333 | CR2: =AVERAGE(M2:R2) -> 83.5 | CS2: =AVERAGE(Y2:AD2) -> 82.333333 | CT2: =AVERAGE(S2:X2) -> 88.166667 | CU2: =AVERAGE(AE2:AJ2) -> 83.833333 | CV2: =AVERAGE(AQ2:AR2) -> 81.5 | CW2: =AVERAGE(AS2:AV2) -> 81.75 | CX2: =AVERAGE(CA2:CB2) -> 84.5 | CY2: =AVERAGE(BA2:BB2) -> 83.5 | CZ2: =AVERAGE(AY2:AZ2) -> 86 | DA2: =AVERAGE(AW2:AX2) -> 80.5 | DB2: =AVERAGE(BE2:BF2) -> 82.5 | DC2: =AVERAGE(BG2:BH2) -> 75.5 | DD2: =AVERAGE(BC2:BD2) -> 83 | DE2: =AVERAGE(BI2:BL2) -> 82 | DF2: =AVERAGE(BM2:BP2) -> 85.75 | DG2: =AVERAGE(BQ2:BT2) -> 84.25 | DH2: =AVERAGE(BW2:BZ2) -> 87.25 | DI2: =AVERAGE(BU2:BV2) -> 87 | DJ2: =AVERAGE(AK2:AL2) -> 85 | DK2: =AVERAGE(CQ2:DJ2) -> 83.583333
A3: 2 | B3: ='DATA US'!B16 -> 222310002 | C3: ='DATA US'!F16 -> BEKASI | D3: ='DATA US'!G16 -> 24 Maret 2007 | E3: ='DATA US'!C16 -> 0077315289 | F3: ='DATA US'!D16 -> AKSAY SETIA AJI | G3: 82 | H3: 80 | I3: 83 | J3: 80 | K3: 83 | L3: 85 | M3: 81 | N3: 84 | O3: 80 | P3: 83 | Q3: 83 | R3: 84 | S3: 80 | T3: 79 | U3: 85 | V3: 87 | W3: 84 | X3: 87 | Y3: 75 | Z3: 77 | AA3: 80 | AB3: 83 | AC3: 82 | AD3: 91 | AE3: 77 | AF3: 77 | AG3: 81 | AH3: 80 | AI3: 84 | AJ3: 90 | AK3: 85 | AL3: 85 | AM3: - | AN3: - | AO3: - | AP3: - | AQ3: 83 | AR3: 80 | AS3: 80 | AT3: 81 | AU3: 88 | AV3: 83 | AW3: 77 | AX3: 81 | AY3: 86 | AZ3: 86 | BA3: 85 | BB3: 85 | BC3: 83 | BD3: 80 | BE3: 83 | BF3: 80 | BG3: 75 | BH3: 76 | BI3: 81 | BJ3: 83 | BK3: 83 | BL3: 86 | BM3: 83 | BN3: 85 | BO3: 87 | BP3: 88 | BQ3: 83 | BR3: 83 | BS3: 86 | BT3: 86 | BU3: 83 | BV3: 88 | BW3: 86 | BX3: 86 | BY3: 81 | BZ3: 88 | CA3: 80 | CB3: 85 | CC3: PT. Sohou Kikaku Indonesia | CD3: MM2100 Jl. Lombok I, N- 16 Cikarang Barat | CE3: 27 Nov 2023 - 27 Agt 2024 | CF3: A | CK3: 89.666667 | CL3: 83.666667 | CM3: 81 | CN3: 88 | CO3: 83 | CP3: 90.166667 | CQ3: =AVERAGE(G3:L3) -> 82.166667 | CR3: =AVERAGE(M3:R3) -> 82.5 | CS3: =AVERAGE(Y3:AD3) -> 81.333333 | CT3: =AVERAGE(S3:X3) -> 83.666667 | CU3: =AVERAGE(AE3:AJ3) -> 81.5 | CV3: =AVERAGE(AQ3:AR3) -> 81.5 | CW3: =AVERAGE(AS3:AV3) -> 83 | CX3: =AVERAGE(CA3:CB3) -> 82.5 | CY3: =AVERAGE(BA3:BB3) -> 85 | CZ3: =AVERAGE(AY3:AZ3) -> 86 | DA3: =AVERAGE(AW3:AX3) -> 79 | DB3: =AVERAGE(BE3:BF3) -> 81.5 | DC3: =AVERAGE(BG3:BH3) -> 75.5 | DD3: =AVERAGE(BC3:BD3) -> 81.5 | DE3: =AVERAGE(BI3:BL3) -> 83.25 | DF3: =AVERAGE(BM3:BP3) -> 85.75 | DG3: =AVERAGE(BQ3:BT3) -> 84.5 | DH3: =AVERAGE(BW3:BZ3) -> 85.25 | DI3: =AVERAGE(BU3:BV3) -> 85.5 | DJ3: =AVERAGE(AK3:AL3) -> 85 | DK3: =AVERAGE(CQ3:DJ3) -> 82.795833
A4: 3 | B4: ='DATA US'!B17 -> 222310003 | C4: ='DATA US'!F17 -> BEKASI | D4: ='DATA US'!G17 -> 30 Juni 2007 | E4: ='DATA US'!C17 -> 0078124071 | F4: ='DATA US'!D17 -> ALFRIYANSYAH FINDO SALMAN | G4: 82 | H4: 78 | I4: 84 | J4: 83 | K4: 82 | L4: 83 | M4: 79 | N4: 81 | O4: 80 | P4: 83 | Q4: 83 | R4: 83 | S4: 80 | T4: 79 | U4: 78 | V4: 85 | W4: 80 | X4: 83 | Y4: 75 | Z4: 75 | AA4: 78 | AB4: 79 | AC4: 82 | AD4: 86 | AE4: 84 | AF4: 77 | AG4: 80 | AH4: 80 | AI4: 84 | AJ4: 85 | AK4: 82 | AL4: 84 | AM4: - | AN4: - | AO4: - | AP4: - | AQ4: 83 | AR4: 79 | AS4: 80 | AT4: 81 | AU4: 89 | AV4: 85 | AW4: 77 | AX4: 81 | AY4: 84 | AZ4: 85 | BA4: 82 | BB4: 83 | BC4: 75 | BD4: 78 | BE4: 75 | BF4: 76 | BG4: 75 | BH4: 75 | BI4: 79 | BJ4: 80 | BK4: 84 | BL4: 83 | BM4: 84 | BN4: 85 | BO4: 83 | BP4: 84 | BQ4: 81 | BR4: 82 | BS4: 83 | BT4: 83 | BU4: 80 | BV4: 86 | BW4: 83 | BX4: 84 | BY4: 81 | BZ4: 86 | CA4: 79 | CB4: 82 | CC4: PT. Alcomexindo | CD4: Kp. Mariuk Rt 004 rw 002 Gandamekar Kec.Cikarang Barat | CE4: 7 Mei 2024 - 7 Nov 2024 | CF4: B | CK4: 88.333333 | CL4: 83.666667 | CM4: 81 | CN4: 87 | CO4: 82.25 | CP4: 88.527778 | CQ4: =AVERAGE(G4:L4) -> 82 | CR4: =AVERAGE(M4:R4) -> 81.5 | CS4: =AVERAGE(Y4:AD4) -> 79.166667 | CT4: =AVERAGE(S4:X4) -> 80.833333 | CU4: =AVERAGE(AE4:AJ4) -> 81.666667 | CV4: =AVERAGE(AQ4:AR4) -> 81 | CW4: =AVERAGE(AS4:AV4) -> 83.75 | CX4: =AVERAGE(CA4:CB4) -> 80.5 | CY4: =AVERAGE(BA4:BB4) -> 82.5 | CZ4: =AVERAGE(AY4:AZ4) -> 84.5 | DA4: =AVERAGE(AW4:AX4) -> 79 | DB4: =AVERAGE(BE4:BF4) -> 75.5 | DC4: =AVERAGE(BG4:BH4) -> 75 | DD4: =AVERAGE(BC4:BD4) -> 76.5 | DE4: =AVERAGE(BI4:BL4) -> 81.5 | DF4: =AVERAGE(BM4:BP4) -> 84 | DG4: =AVERAGE(BQ4:BT4) -> 82.25 | DH4: =AVERAGE(BW4:BZ4) -> 83.5 | DI4: =AVERAGE(BU4:BV4) -> 83 | DJ4: =AVERAGE(AK4:AL4) -> 83 | DK4: =AVERAGE(CQ4:DJ4) -> 81.033333
A5: 4 | B5: ='DATA US'!B18 -> 222310004 | C5: ='DATA US'!F18 -> CIAMIS | D5: ='DATA US'!G18 -> 20 Oktober 2006 | E5: ='DATA US'!C18 -> 0134157802 | F5: ='DATA US'!D18 -> ARIEF OKTA PRATAMA | G5: 80 | H5: 78 | I5: 83 | J5: 83 | K5: 82 | L5: 83 | M5: 78 | N5: 81 | O5: 79 | P5: 84 | Q5: 83 | R5: 84 | S5: 78 | T5: 79 | U5: 78 | V5: 80 | W5: 80 | X5: 83 | Y5: 75 | Z5: 75 | AA5: 78 | AB5: 79 | AC5: 83 | AD5: 86 | AE5: 79 | AF5: 77 | AG5: 79 | AH5: 80 | AI5: 82 | AJ5: 85 | AK5: 81 | AL5: 79 | AM5: - | AN5: - | AO5: - | AP5: - | AQ5: 83 | AR5: 81 | AS5: 80 | AT5: 81 | AU5: 83 | AV5: 82 | AW5: 78 | AX5: 81 | AY5: 84 | AZ5: 82 | BA5: 83 | BB5: 84 | BC5: 75 | BD5: 81 | BE5: 75 | BF5: 82 | BG5: 75 | BH5: 76 | BI5: 78 | BJ5: 79 | BK5: 83 | BL5: 83 | BM5: 78 | BN5: 79 | BO5: 81 | BP5: 82 | BQ5: 78 | BR5: 81 | BS5: 84 | BT5: 83 | BU5: 81 | BV5: 87 | BW5: 85 | BX5: 85 | BY5: 82 | BZ5: 87 | CA5: 81 | CB5: 81 | CC5: PT. Alcomexindo | CD5: Kp. Mariuk Rt 004 rw 002 Gandamekar Kec.Cikarang Barat | CE5: 20 Juli 2024- 20 Nov 2024 | CF5: B | CK5: 88.666667 | CL5: 82.333333 | CM5: 81 | CN5: 87 | CO5: 80 | CP5: 86.027778 | CQ5: =AVERAGE(G5:L5) -> 81.5 | CR5: =AVERAGE(M5:R5) -> 81.5 | CS5: =AVERAGE(Y5:AD5) -> 79.333333 | CT5: =AVERAGE(S5:X5) -> 79.666667 | CU5: =AVERAGE(AE5:AJ5) -> 80.333333 | CV5: =AVERAGE(AQ5:AR5) -> 82 | CW5: =AVERAGE(AS5:AV5) -> 81.5 | CX5: =AVERAGE(CA5:CB5) -> 81 | CY5: =AVERAGE(BA5:BB5) -> 83.5 | CZ5: =AVERAGE(AY5:AZ5) -> 83 | DA5: =AVERAGE(AW5:AX5) -> 79.5 | DB5: =AVERAGE(BE5:BF5) -> 78.5 | DC5: =AVERAGE(BG5:BH5) -> 75.5 | DD5: =AVERAGE(BC5:BD5) -> 78 | DE5: =AVERAGE(BI5:BL5) -> 80.75 | DF5: =AVERAGE(BM5:BP5) -> 80 | DG5: =AVERAGE(BQ5:BT5) -> 81.5 | DH5: =AVERAGE(BW5:BZ5) -> 84.75 | DI5: =AVERAGE(BU5:BV5) -> 84 | DJ5: =AVERAGE(AK5:AL5) -> 80 | DK5: =AVERAGE(CQ5:DJ5) -> 80.791667
A6: 5 | B6: ='DATA US'!B19 -> 222310005 | C6: ='DATA US'!F19 -> BEKASI | D6: ='DATA US'!G19 -> 8 Agustus 2007 | E6: ='DATA US'!C19 -> 0072858452 | F6: ='DATA US'!D19 -> DEDEN RIZKY SAPUTRA | G6: 84 | H6: 84 | I6: 85 | J6: 86 | K6: 88 | L6: 90 | M6: 86 | N6: 86 | O6: 85 | P6: 86 | Q6: 86 | R6: 90 | S6: 79 | T6: 84 | U6: 91 | V6: 91 | W6: 91 | X6: 90 | Y6: 79 | Z6: 78 | AA6: 86 | AB6: 86 | AC6: 89 | AD6: 91 | AE6: 82 | AF6: 79 | AG6: 85 | AH6: 87 | AI6: 87 | AJ6: 95 | AK6: 87 | AL6: 88 | AM6: - | AN6: - | AO6: - | AP6: - | AQ6: 83 | AR6: 85 | AS6: 80 | AT6: 82 | AU6: 84 | AV6: 84 | AW6: 83 | AX6: 85 | AY6: 87 | AZ6: 86 | BA6: 87 | BB6: 87 | BC6: 88 | BD6: 89 | BE6: 88 | BF6: 89 | BG6: 76 | BH6: 82 | BI6: 85 | BJ6: 88 | BK6: 84 | BL6: 88 | BM6: 88 | BN6: 86 | BO6: 89 | BP6: 90 | BQ6: 86 | BR6: 89 | BS6: 88 | BT6: 88 | BU6: 91 | BV6: 90 | BW6: 88 | BX6: 88 | BY6: 87 | BZ6: 90 | CA6: 85 | CB6: 87 | CC6: PT. SBP Indonesia | CD6: Kawasan Industri MM2100 Jatiwangi Bekasi | CE6: 12 Maret 2024 - 31 Mei 2024 | CF6: A | CK6: 91.666667 | CL6: 88.666667 | CM6: 93 | CN6: 87 | CO6: 82.25 | CP6: 89.555556 | CQ6: =AVERAGE(G6:L6) -> 86.166667 | CR6: =AVERAGE(M6:R6) -> 86.5 | CS6: =AVERAGE(Y6:AD6) -> 84.833333 | CT6: =AVERAGE(S6:X6) -> 87.666667 | CU6: =AVERAGE(AE6:AJ6) -> 85.833333 | CV6: =AVERAGE(AQ6:AR6) -> 84 | CW6: =AVERAGE(AS6:AV6) -> 82.5 | CX6: =AVERAGE(CA6:CB6) -> 86 | CY6: =AVERAGE(BA6:BB6) -> 87 | CZ6: =AVERAGE(AY6:AZ6) -> 86.5 | DA6: =AVERAGE(AW6:AX6) -> 84 | DB6: =AVERAGE(BE6:BF6) -> 88.5 | DC6: =AVERAGE(BG6:BH6) -> 79 | DD6: =AVERAGE(BC6:BD6) -> 88.5 | DE6: =AVERAGE(BI6:BL6) -> 86.25 | DF6: =AVERAGE(BM6:BP6) -> 88.25 | DG6: =AVERAGE(BQ6:BT6) -> 87.75 | DH6: =AVERAGE(BW6:BZ6) -> 88.25 | DI6: =AVERAGE(BU6:BV6) -> 90.5 | DJ6: =AVERAGE(AK6:AL6) -> 87.5 | DK6: =AVERAGE(CQ6:DJ6) -> 86.275
A7: 6 | B7: ='DATA US'!B20 -> 222310006 | C7: ='DATA US'!F20 -> BEKASI | D7: ='DATA US'!G20 -> 8 Agustus 2007 | E7: ='DATA US'!C20 -> 0073210618 | F7: ='DATA US'!D20 -> DENI RAHMAT SAPUTRA | G7: 85 | H7: 85 | I7: 87 | J7: 88 | K7: 86 | L7: 87 | M7: 86 | N7: 86 | O7: 85 | P7: 85 | Q7: 86 | R7: 90 | S7: 81 | T7: 87 | U7: 84 | V7: 91 | W7: 91 | X7: 91 | Y7: 80 | Z7: 80 | AA7: 87 | AB7: 87 | AC7: 88 | AD7: 91 | AE7: 82 | AF7: 78 | AG7: 84 | AH7: 83 | AI7: 90 | AJ7: 95 | AK7: 87 | AL7: 89 | AM7: - | AN7: - | AO7: - | AP7: - | AQ7: 83 | AR7: 84 | AS7: 81 | AT7: 82 | AU7: 89 | AV7: 87 | AW7: 81 | AX7: 85 | AY7: 86 | AZ7: 86 | BA7: 86 | BB7: 86 | BC7: 86 | BD7: 90 | BE7: 88 | BF7: 88 | BG7: 75 | BH7: 76 | BI7: 85 | BJ7: 88 | BK7: 83 | BL7: 88 | BM7: 88 | BN7: 86 | BO7: 89 | BP7: 90 | BQ7: 87 | BR7: 87 | BS7: 88 | BT7: 88 | BU7: 90 | BV7: 90 | BW7: 87 | BX7: 88 | BY7: 87 | BZ7: 90 | CA7: 86 | CB7: 88 | CC7: PT. Sliontec Ekadharma | CD7: Kawasan Industri MM2100 Jatiwangi Bekasi | CE7: 2 Mei 2024 - 2 Agustus 2024 | CF7: B | CK7: 91.666667 | CL7: 87.666667 | CM7: 95 | CN7: 80 | CO7: 82.25 | CP7: 89.333333 | CQ7: =AVERAGE(G7:L7) -> 86.333333 | CR7: =AVERAGE(M7:R7) -> 86.333333 | CS7: =AVERAGE(Y7:AD7) -> 85.5 | CT7: =AVERAGE(S7:X7) -> 87.5 | CU7: =AVERAGE(AE7:AJ7) -> 85.333333 | CV7: =AVERAGE(AQ7:AR7) -> 83.5 | CW7: =AVERAGE(AS7:AV7) -> 84.75 | CX7: =AVERAGE(CA7:CB7) -> 87 | CY7: =AVERAGE(BA7:BB7) -> 86 | CZ7: =AVERAGE(AY7:AZ7) -> 86 | DA7: =AVERAGE(AW7:AX7) -> 83 | DB7: =AVERAGE(BE7:BF7) -> 88 | DC7: =AVERAGE(BG7:BH7) -> 75.5 | DD7: =AVERAGE(BC7:BD7) -> 88 | DE7: =AVERAGE(BI7:BL7) -> 86 | DF7: =AVERAGE(BM7:BP7) -> 88.25 | DG7: =AVERAGE(BQ7:BT7) -> 87.5 | DH7: =AVERAGE(BW7:BZ7) -> 88 | DI7: =AVERAGE(BU7:BV7) -> 90 | DJ7: =AVERAGE(AK7:AL7) -> 88 | DK7: =AVERAGE(CQ7:DJ7) -> 86.025
